Workbook

Sheet BIData
A2: =IFERROR(IF(0=LEN(ReferenceData!$A$2),"",ReferenceData!$A$2),"") -> Description | B2: =IFERROR(IF(0=LEN(ReferenceData!$B$2),"",ReferenceData!$B$2),"") -> Ticker | C2: =IFERROR(IF(0=LEN(ReferenceData!$C$2),"",ReferenceData!$C$2),"") -> Field ID | D2: =IFERROR(IF(0=LEN(ReferenceData!$D$2),"",ReferenceData!$D$2),"") -> Field Mnemonic | E2: =IFERROR(IF(0=LEN(ReferenceData!$E$2),"",ReferenceData!$E$2),"") -> Data State | F2: =IFERROR(IF(0=LEN(ReferenceData!$F$2),"",ReferenceData!$F$2),"") -> 2025 Q2 | G2: =IFERROR(IF(0=LEN(ReferenceData!$G$2),"",ReferenceData!$G$2),"") -> 2025 Q1 | H2: =IFERROR(IF(0=LEN(ReferenceData!$H$2),"",ReferenceData!$H$2),"") -> 2024 Q4 | I2: =IFERROR(IF(0=LEN(ReferenceData!$I$2),"",ReferenceData!$I$2),"") -> 2024 Q3 | J2: =IFERROR(IF(0=LEN(ReferenceData!$J$2),"",ReferenceData!$J$2),"") -> 2024 Q2 | K2: =IFERROR(IF(0=LEN(ReferenceData!$K$2),"",ReferenceData!$K$2),"") -> 2024 Q1 | L2: =IFERROR(IF(0=LEN(ReferenceData!$L$2),"",ReferenceData!$L$2),"") -> 2023 Q4 | M2: =IFERROR(IF(0=LEN(ReferenceData!$M$2),"",ReferenceData!$M$2),"") -> 2023 Q3 | N2: =IFERROR(IF(0=LEN(ReferenceData!$N$2),"",ReferenceData!$N$2),"") -> 2023 Q2 | O2: =IFERROR(IF(0=LEN(ReferenceData!$O$2),"",ReferenceData!$O$2),"") -> 2023 Q1 | P2: =IFERROR(IF(0=LEN(ReferenceData!$P$2),"",ReferenceData!$P$2),"") -> 2022 Q4 | Q2: =IFERROR(IF(0=LEN(ReferenceData!$Q$2),"",ReferenceData!$Q$2),"") -> 2022 Q3 | R2: =IFERROR(IF(0=LEN(ReferenceData!$R$2),"",ReferenceData!$R$2),"") -> 2022 Q2 | S2: =IFERROR(IF(0=LEN(ReferenceData!$S$2),"",ReferenceData!$S$2),"") -> 2022 Q1 | T2: =IFERROR(IF(0=LEN(ReferenceData!$T$2),"",ReferenceData!$T$2),"") -> 2021 Q4 | U2: =IFERROR(IF(0=LEN(ReferenceData!$U$2),"",ReferenceData!$U$2),"") -> 2021 Q3 | V2: =IFERROR(IF(0=LEN(ReferenceData!$V$2),"",ReferenceData!$V$2),"") -> 2021 Q2 | W2: =IFERROR(IF(0=LEN(ReferenceData!$W$2),"",ReferenceData!$W$2),"") -> 2021 Q1 | X2: =IFERROR(IF(0=LEN(ReferenceData!$X$2),"",ReferenceData!$X$2),"") -> 2020 Q4 | Y2: =IFERROR(IF(0=LEN(ReferenceData!$Y$2),"",ReferenceData!$Y$2),"") -> 2020 Q3 | Z2: =IFERROR(IF(0=LEN(ReferenceData!$Z$2),"",ReferenceData!$Z$2),"") -> 2020 Q2 | AA2: =IFERROR(IF(0=LEN(ReferenceData!$AA$2),"",ReferenceData!$AA$2),"") -> 2020 Q1 | AB2: =IFERROR(IF(0=LEN(ReferenceData!$AB$2),"",ReferenceData!$AB$2),"") -> 2019 Q4 | AC2: =IFERROR(IF(0=LEN(ReferenceData!$AC$2),"",ReferenceData!$AC$2),"") -> 2019 Q3 | AD2: =IFERROR(IF(0=LEN(ReferenceData!$AD$2),"",ReferenceData!$AD$2),"") -> 2019 Q2 | AE2: =IFERROR(IF(0=LEN(ReferenceData!$AE$2),"",ReferenceData!$AE$2),"") -> 2019 Q1 | AF2: =IFERROR(IF(0=LEN(ReferenceData!$AF$2),"",ReferenceData!$AF$2),"") -> 2018 Q4 | AG2: =IFERROR(IF(0=LEN(ReferenceData!$AG$2),"",ReferenceData!$AG$2),"") -> 2018 Q3 | AH2: =IFERROR(IF(0=LEN(ReferenceData!$AH$2),"",ReferenceData!$AH$2),"") -> 2018 Q2 | AI2: =IFERROR(IF(0=LEN(ReferenceData!$AI$2),"",ReferenceData!$AI$2),"") -> 2018 Q1 | AJ2: =IFERROR(IF(0=LEN(ReferenceData!$AJ$2),"",ReferenceData!$AJ$2),"") -> 2017 Q4 | AK2: =IFERROR(IF(0=LEN(ReferenceData!$AK$2),"",ReferenceData!$AK$2),"") -> 2017 Q3 | AL2: =IFERROR(IF(0=LEN(ReferenceData!$AL$2),"",ReferenceData!$AL$2),"") -> 2017 Q2 | AM2: =IFERROR(IF(0=LEN(ReferenceData!$AM$2),"",ReferenceData!$AM$2),"") -> 2017 Q1 | AN2: =IFERROR(IF(0=LEN(ReferenceData!$AN$2),"",ReferenceData!$AN$2),"") -> 2016 Q4 | AO2: =IFERROR(IF(0=LEN(ReferenceData!$AO$2),"",ReferenceData!$AO$2),"") -> 2016 Q3 | AP2: =IFERROR(IF(0=LEN(ReferenceData!$AP$2),"",ReferenceData!$AP$2),"") -> 2016 Q2 | AQ2: =IFERROR(IF(0=LEN(ReferenceData!$AQ$2),"",ReferenceData!$AQ$2),"") -> 2016 Q1 | AR2: =IFERROR(IF(0=LEN(ReferenceData!$AR$2),"",ReferenceData!$AR$2),"") -> 2015 Q4 | AS2: =IFERROR(IF(0=LEN(ReferenceData!$AS$2),"",ReferenceData!$AS$2),"") -> 2015 Q3 | AT2: =IFERROR(IF(0=LEN(ReferenceData!$AT$2),"",ReferenceData!$AT$2),"") -> 2015 Q2 | AU2: =IFERROR(IF(0=LEN(ReferenceData!$AU$2),"",ReferenceData!$AU$2),"") -> 2015 Q1 | AV2: =IFERROR(IF(0=LEN(ReferenceData!$AV$2),"",ReferenceData!$AV$2),"") -> 2014 Q4 | AW2: =IFERROR(IF(0=LEN(ReferenceData!$AW$2),"",ReferenceData!$AW$2),"") -> 2014 Q3 | AX2: =IFERROR(IF(0=LEN(ReferenceData!$AX$2),"",ReferenceData!$AX$2),"") -> 2014 Q2 | AY2: =IFERROR(IF(0=LEN(ReferenceData!$AY$2),"",ReferenceData!$AY$2),"") -> 2014 Q1 | AZ2: =IFERROR(IF(0=LEN(ReferenceData!$AZ$2),"",ReferenceData!$AZ$2),"") -> 2013 Q4 | BA2: =IFERROR(IF(0=LEN(ReferenceData!$BA$2),"",ReferenceData!$BA$2),"") -> 2013 Q3 | BB2: =IFERROR(IF(0=LEN(ReferenceData!$BB$2),"",ReferenceData!$BB$2),"") -> 2013 Q2 | BC2: =IFERROR(IF(0=LEN(ReferenceData!$BC$2),"",ReferenceData!$BC$2),"") -> 2013 Q1 | BD2: =IFERROR(IF(0=LEN(ReferenceData!$BD$2),"",ReferenceData!$BD$2),"") -> 2012 Q4 | BE2: =IFERROR(IF(0=LEN(ReferenceData!$BE$2),"",ReferenceData!$BE$2),"") -> 2012 Q3 | BF2: =IFERROR(IF(0=LEN(ReferenceData!$BF$2),"",ReferenceData!$BF$2),"") -> 2012 Q2 | BG2: =IFERROR(IF(0=LEN(ReferenceData!$BG$2),"",ReferenceData!$BG$2),"") -> 2012 Q1 | BH2: =IFERROR(IF(0=LEN(ReferenceData!$BH$2),"",ReferenceData!$BH$2),"") -> 2011 Q4 | BI2: =IFERROR(IF(0=LEN(ReferenceData!$BI$2),"",ReferenceData!$BI$2),"") -> 2011 Q3 | BJ2: =IFERROR(IF(0=LEN(ReferenceData!$BJ$2),"",ReferenceData!$BJ$2),"") -> 2011 Q2 | BK2: =IFERROR(IF(0=LEN(ReferenceData!$BK$2),"",ReferenceData!$BK$2),"") -> 2011 Q1 | BL2: =IFERROR(IF(0=LEN(ReferenceData!$BL$2),"",ReferenceData!$BL$2),"") -> 2010 Q4 | BM2: =IFERROR(IF(0=LEN(ReferenceData!$BM$2),"",ReferenceData!$BM$2),"") -> 2010 Q3
A3: =IFERROR(IF(0=LEN(ReferenceData!$A$3),"",ReferenceData!$A$3),"") -> North America (Bil.) - US (USD) | B3: =IFERROR(IF(0=LEN(ReferenceData!$B$3),"",ReferenceData!$B$3),"") -> GDP CUR$ Index | C3: =IFERROR(IF(0=LEN(ReferenceData!$C$3),"",ReferenceData!$C$3),"") -> PR005 | D3: =IFERROR(IF(0=LEN(ReferenceData!$D$3),"",ReferenceData!$D$3),"") -> PX_LAST | E3: =IFERROR(IF(0=LEN(ReferenceData!$E$3),"",ReferenceData!$E$3),"") -> Dynamic | F3: =IFERROR(IF(0=LEN(ReferenceData!$F$3),"",ReferenceData!$F$3),"") -> 30331.117 | G3: =IFERROR(IF(0=LEN(ReferenceData!$G$3),"",ReferenceData!$G$3),"") -> 29962.047 | H3: =IFERROR(IF(0=LEN(ReferenceData!$H$3),"",ReferenceData!$H$3),"") -> 29723.864 | I3: =IFERROR(IF(0=LEN(ReferenceData!$I$3),"",ReferenceData!$I$3),"") -> 29374.914 | J3: =IFERROR(IF(0=LEN(ReferenceData!$J$3),"",ReferenceData!$J$3),"") -> 29016.714 | K3: =IFERROR(IF(0=LEN(ReferenceData!$K$3),"",ReferenceData!$K$3),"") -> 28624.069 | L3: =IFERROR(IF(0=LEN(ReferenceData!$L$3),"",ReferenceData!$L$3),"") -> 28296.967 | M3: =IFERROR(IF(0=LEN(ReferenceData!$M$3),"",ReferenceData!$M$3),"") -> 27967.697 | N3: =IFERROR(IF(0=LEN(ReferenceData!$N$3),"",ReferenceData!$N$3),"") -> 27453.815 | O3: =IFERROR(IF(0=LEN(ReferenceData!$O$3),"",ReferenceData!$O$3),"") -> 27164.359 | P3: =IFERROR(IF(0=LEN(ReferenceData!$P$3),"",ReferenceData!$P$3),"") -> 26734.277 | Q3: =IFERROR(IF(0=LEN(ReferenceData!$Q$3),"",ReferenceData!$Q$3),"") -> 26272.011 | R3: =IFERROR(IF(0=LEN(ReferenceData!$R$3),"",ReferenceData!$R$3),"") -> 25805.791 | S3: =IFERROR(IF(0=LEN(ReferenceData!$S$3),"",ReferenceData!$S$3),"") -> 25215.491 | T3: =IFERROR(IF(0=LEN(ReferenceData!$T$3),"",ReferenceData!$T$3),"") -> 24777.038 | U3: =IFERROR(IF(0=LEN(ReferenceData!$U$3),"",ReferenceData!$U$3),"") -> 23921.991 | V3: =IFERROR(IF(0=LEN(ReferenceData!$V$3),"",ReferenceData!$V$3),"") -> 23368.861 | W3: =IFERROR(IF(0=LEN(ReferenceData!$W$3),"",ReferenceData!$W$3),"") -> 22656.793 | X3: =IFERROR(IF(0=LEN(ReferenceData!$X$3),"",ReferenceData!$X$3),"") -> 22068.767 | Y3: =IFERROR(IF(0=LEN(ReferenceData!$Y$3),"",ReferenceData!$Y$3),"") -> 21684.551 | Z3: =IFERROR(IF(0=LEN(ReferenceData!$Z$3),"",ReferenceData!$Z$3),"") -> 19935.444 | AA3: =IFERROR(IF(0=LEN(ReferenceData!$AA$3),"",ReferenceData!$AA$3),"") -> 21727.657 | AB3: =IFERROR(IF(0=LEN(ReferenceData!$AB$3),"",ReferenceData!$AB$3),"") -> 21933.217 | AC3: =IFERROR(IF(0=LEN(ReferenceData!$AC$3),"",ReferenceData!$AC$3),"") -> 21717.171 | AD3: =IFERROR(IF(0=LEN(ReferenceData!$AD$3),"",ReferenceData!$AD$3),"") -> 21397.938 | AE3: =IFERROR(IF(0=LEN(ReferenceData!$AE$3),"",ReferenceData!$AE$3),"") -> 21111.6 | AF3: =IFERROR(IF(0=LEN(ReferenceData!$AF$3),"",ReferenceData!$AF$3),"") -> 20917.867 | AG3: =IFERROR(IF(0=LEN(ReferenceData!$AG$3),"",ReferenceData!$AG$3),"") -> 20798.73 | AH3: =IFERROR(IF(0=LEN(ReferenceData!$AH$3),"",ReferenceData!$AH$3),"") -> 20580.912 | AI3: =IFERROR(IF(0=LEN(ReferenceData!$AI$3),"",ReferenceData!$AI$3),"") -> 20328.553 | AJ3: =IFERROR(IF(0=LEN(ReferenceData!$AJ$3),"",ReferenceData!$AJ$3),"") -> 20037.088 | AK3: =IFERROR(IF(0=LEN(ReferenceData!$AK$3),"",ReferenceData!$AK$3),"") -> 19692.595 | AL3: =IFERROR(IF(0=LEN(ReferenceData!$AL$3),"",ReferenceData!$AL$3),"") -> 19438.643 | AM3: =IFERROR(IF(0=LEN(ReferenceData!$AM$3),"",ReferenceData!$AM$3),"") -> 19280.084 | AN3: =IFERROR(IF(0=LEN(ReferenceData!$AN$3),"",ReferenceData!$AN$3),"") -> 19089.379 | AO3: =IFERROR(IF(0=LEN(ReferenceData!$AO$3),"",ReferenceData!$AO$3),"") -> 18892.639 | AP3: =IFERROR(IF(0=LEN(ReferenceData!$AP$3),"",ReferenceData!$AP$3),"") -> 18711.702 | AQ3: =IFERROR(IF(0=LEN(ReferenceData!$AQ$3),"",ReferenceData!$AQ$3),"") -> 18525.933 | AR3: =IFERROR(IF(0=LEN(ReferenceData!$AR$3),"",ReferenceData!$AR$3),"") -> 18435.137 | AS3: =IFERROR(IF(0=LEN(ReferenceData!$AS$3),"",ReferenceData!$AS$3),"") -> 18401.626 | AT3: =IFERROR(IF(0=LEN(ReferenceData!$AT$3),"",ReferenceData!$AT$3),"") -> 18279.784 | AU3: =IFERROR(IF(0=LEN(ReferenceData!$AU$3),"",ReferenceData!$AU$3),"") -> 18063.529 | AV3: =IFERROR(IF(0=LEN(ReferenceData!$AV$3),"",ReferenceData!$AV$3),"") -> 17912.079 | AW3: =IFERROR(IF(0=LEN(ReferenceData!$AW$3),"",ReferenceData!$AW$3),"") -> 17804.228 | AX3: =IFERROR(IF(0=LEN(ReferenceData!$AX$3),"",ReferenceData!$AX$3),"") -> 17518.508 | AY3: =IFERROR(IF(0=LEN(ReferenceData!$AY$3),"",ReferenceData!$AY$3),"") -> 17197.738 | AZ3: =IFERROR(IF(0=LEN(ReferenceData!$AZ$3),"",ReferenceData!$AZ$3),"") -> 17192.019 | BA3: =IFERROR(IF(0=LEN(ReferenceData!$BA$3),"",ReferenceData!$BA$3),"") -> 16953.838 | BB3: =IFERROR(IF(0=LEN(ReferenceData!$BB$3),"",ReferenceData!$BB$3),"") -> 16728.687 | BC3: =IFERROR(IF(0=LEN(ReferenceData!$BC$3),"",ReferenceData!$BC$3),"") -> 16648.189 | BD3: =IFERROR(IF(0=LEN(ReferenceData!$BD$3),"",ReferenceData!$BD$3),"") -> 16420.419 | BE3: =IFERROR(IF(0=LEN(ReferenceData!$BE$3),"",ReferenceData!$BE$3),"") -> 16319.54 | BF3: =IFERROR(IF(0=LEN(ReferenceData!$BF$3),"",ReferenceData!$BF$3),"") -> 16207.115 | BG3: =IFERROR(IF(0=LEN(ReferenceData!$BG$3),"",ReferenceData!$BG$3),"") -> 16068.805 | BH3: =IFERROR(IF(0=LEN(ReferenceData!$BH$3),"",ReferenceData!$BH$3),"") -> 15842.259 | BI3: =IFERROR(IF(0=LEN(ReferenceData!$BI$3),"",ReferenceData!$BI$3),"") -> 15647.681 | BJ3: =IFERROR(IF(0=LEN(ReferenceData!$BJ$3),"",ReferenceData!$BJ$3),"") -> 15557.539 | BK3: =IFERROR(IF(0=LEN(ReferenceData!$BK$3),"",ReferenceData!$BK$3),"") -> 15351.448 | BL3: =IFERROR(IF(0=LEN(ReferenceData!$BL$3),"",ReferenceData!$BL$3),"") -> 15309.474 | BM3: =IFERROR(IF(0=LEN(ReferenceData!$BM$3),"",ReferenceData!$BM$3),"") -> 15141.607
A4: =IFERROR(IF(0=LEN(ReferenceData!$A$4),"",ReferenceData!$A$4),"") -> Personal Consumption Expenditures | B4: =IFERROR(IF(0=LEN(ReferenceData!$B$4),"",ReferenceData!$B$4),"") -> GDP$PCE Index | C4: =IFERROR(IF(0=LEN(ReferenceData!$C$4),"",ReferenceData!$C$4),"") -> PR005 | D4: =IFERROR(IF(0=LEN(ReferenceData!$D$4),"",ReferenceData!$D$4),"") -> PX_LAST | E4: =IFERROR(IF(0=LEN(ReferenceData!$E$4),"",ReferenceData!$E$4),"") -> Dynamic | F4: =IFERROR(IF(0=LEN(ReferenceData!$F$4),"",ReferenceData!$F$4),"") -> 20640.878 | G4: =IFERROR(IF(0=LEN(ReferenceData!$G$4),"",ReferenceData!$G$4),"") -> 20461.602 | H4: =IFERROR(IF(0=LEN(ReferenceData!$H$4),"",ReferenceData!$H$4),"") -> 20255.455 | I4: =IFERROR(IF(0=LEN(ReferenceData!$I$4),"",ReferenceData!$I$4),"") -> 19938.425 | J4: =IFERROR(IF(0=LEN(ReferenceData!$J$4),"",ReferenceData!$J$4),"") -> 19682.699 | K4: =IFERROR(IF(0=LEN(ReferenceData!$K$4),"",ReferenceData!$K$4),"") -> 19424.775 | L4: =IFERROR(IF(0=LEN(ReferenceData!$L$4),"",ReferenceData!$L$4),"") -> 19170.154 | M4: =IFERROR(IF(0=LEN(ReferenceData!$M$4),"",ReferenceData!$M$4),"") -> 18928.987 | N4: =IFERROR(IF(0=LEN(ReferenceData!$N$4),"",ReferenceData!$N$4),"") -> 18685.724 | O4: =IFERROR(IF(0=LEN(ReferenceData!$O$4),"",ReferenceData!$O$4),"") -> 18506.211 | P4: =IFERROR(IF(0=LEN(ReferenceData!$P$4),"",ReferenceData!$P$4),"") -> 18108.27 | Q4: =IFERROR(IF(0=LEN(ReferenceData!$Q$4),"",ReferenceData!$Q$4),"") -> 17876.234 | R4: =IFERROR(IF(0=LEN(ReferenceData!$R$4),"",ReferenceData!$R$4),"") -> 17603.753 | S4: =IFERROR(IF(0=LEN(ReferenceData!$S$4),"",ReferenceData!$S$4),"") -> 17175.105 | T4: =IFERROR(IF(0=LEN(ReferenceData!$T$4),"",ReferenceData!$T$4),"") -> 16816.132 | U4: =IFERROR(IF(0=LEN(ReferenceData!$U$4),"",ReferenceData!$U$4),"") -> 16363.876 | V4: =IFERROR(IF(0=LEN(ReferenceData!$V$4),"",ReferenceData!$V$4),"") -> 16016.346 | W4: =IFERROR(IF(0=LEN(ReferenceData!$W$4),"",ReferenceData!$W$4),"") -> 15259.427 | X4: =IFERROR(IF(0=LEN(ReferenceData!$X$4),"",ReferenceData!$X$4),"") -> 14752.732 | Y4: =IFERROR(IF(0=LEN(ReferenceData!$Y$4),"",ReferenceData!$Y$4),"") -> 14478.033 | Z4: =IFERROR(IF(0=LEN(ReferenceData!$Z$4),"",ReferenceData!$Z$4),"") -> 13175.637 | AA4: =IFERROR(IF(0=LEN(ReferenceData!$AA$4),"",ReferenceData!$AA$4),"") -> 14496.227 | AB4: =IFERROR(IF(0=LEN(ReferenceData!$AB$4),"",ReferenceData!$AB$4),"") -> 14701.038 | AC4: =IFERROR(IF(0=LEN(ReferenceData!$AC$4),"",ReferenceData!$AC$4),"") -> 14548.282 | AD4: =IFERROR(IF(0=LEN(ReferenceData!$AD$4),"",ReferenceData!$AD$4),"") -> 14350.662 | AE4: =IFERROR(IF(0=LEN(ReferenceData!$AE$4),"",ReferenceData!$AE$4),"") -> 14150.191 | AF4: =IFERROR(IF(0=LEN(ReferenceData!$AF$4),"",ReferenceData!$AF$4),"") -> 14099.199 | AG4: =IFERROR(IF(0=LEN(ReferenceData!$AG$4),"",ReferenceData!$AG$4),"") -> 14002.199 | AH4: =IFERROR(IF(0=LEN(ReferenceData!$AH$4),"",ReferenceData!$AH$4),"") -> 13891.294 | AI4: =IFERROR(IF(0=LEN(ReferenceData!$AI$4),"",ReferenceData!$AI$4),"") -> 13745.074 | AJ4: =IFERROR(IF(0=LEN(ReferenceData!$AJ$4),"",ReferenceData!$AJ$4),"") -> 13551.401 | AK4: =IFERROR(IF(0=LEN(ReferenceData!$AK$4),"",ReferenceData!$AK$4),"") -> 13325.065 | AL4: =IFERROR(IF(0=LEN(ReferenceData!$AL$4),"",ReferenceData!$AL$4),"") -> 13188.73 | AM4: =IFERROR(IF(0=LEN(ReferenceData!$AM$4),"",ReferenceData!$AM$4),"") -> 13097.306 | AN4: =IFERROR(IF(0=LEN(ReferenceData!$AN$4),"",ReferenceData!$AN$4),"") -> 12921.989 | AO4: =IFERROR(IF(0=LEN(ReferenceData!$AO$4),"",ReferenceData!$AO$4),"") -> 12797.126 | AP4: =IFERROR(IF(0=LEN(ReferenceData!$AP$4),"",ReferenceData!$AP$4),"") -> 12665.124 | AQ4: =IFERROR(IF(0=LEN(ReferenceData!$AQ$4),"",ReferenceData!$AQ$4),"") -> 12523.156 | AR4: =IFERROR(IF(0=LEN(ReferenceData!$AR$4),"",ReferenceData!$AR$4),"") -> 12423.353 | AS4: =IFERROR(IF(0=LEN(ReferenceData!$AS$4),"",ReferenceData!$AS$4),"") -> 12382.494 | AT4: =IFERROR(IF(0=LEN(ReferenceData!$AT$4),"",ReferenceData!$AT$4),"") -> 12264.14 | AU4: =IFERROR(IF(0=LEN(ReferenceData!$AU$4),"",ReferenceData!$AU$4),"") -> 12119.763 | AV4: =IFERROR(IF(0=LEN(ReferenceData!$AV$4),"",ReferenceData!$AV$4),"") -> 12081.561 | AW4: =IFERROR(IF(0=LEN(ReferenceData!$AW$4),"",ReferenceData!$AW$4),"") -> 11959.79 | AX4: =IFERROR(IF(0=LEN(ReferenceData!$AX$4),"",ReferenceData!$AX$4),"") -> 11810.451 | AY4: =IFERROR(IF(0=LEN(ReferenceData!$AY$4),"",ReferenceData!$AY$4),"") -> 11646.001 | AZ4: =IFERROR(IF(0=LEN(ReferenceData!$AZ$4),"",ReferenceData!$AZ$4),"") -> 11551.229 | BA4: =IFERROR(IF(0=LEN(ReferenceData!$BA$4),"",ReferenceData!$BA$4),"") -> 11408.359 | BB4: =IFERROR(IF(0=LEN(ReferenceData!$BB$4),"",ReferenceData!$BB$4),"") -> 11315.681 | BC4: =IFERROR(IF(0=LEN(ReferenceData!$BC$4),"",ReferenceData!$BC$4),"") -> 11277.664 | BD4: =IFERROR(IF(0=LEN(ReferenceData!$BD$4),"",ReferenceData!$BD$4),"") -> 11165.703 | BE4: =IFERROR(IF(0=LEN(ReferenceData!$BE$4),"",ReferenceData!$BE$4),"") -> 11059.393 | BF4: =IFERROR(IF(0=LEN(ReferenceData!$BF$4),"",ReferenceData!$BF$4),"") -> 11005.055 | BG4: =IFERROR(IF(0=LEN(ReferenceData!$BG$4),"",ReferenceData!$BG$4),"") -> 10959.301 | BH4: =IFERROR(IF(0=LEN(ReferenceData!$BH$4),"",ReferenceData!$BH$4),"") -> 10809.186 | BI4: =IFERROR(IF(0=LEN(ReferenceData!$BI$4),"",ReferenceData!$BI$4),"") -> 10755.029 | BJ4: =IFERROR(IF(0=LEN(ReferenceData!$BJ$4),"",ReferenceData!$BJ$4),"") -> 10673.018 | BK4: =IFERROR(IF(0=LEN(ReferenceData!$BK$4),"",ReferenceData!$BK$4),"") -> 10558.195 | BL4: =IFERROR(IF(0=LEN(ReferenceData!$BL$4),"",ReferenceData!$BL$4),"") -> 10430.304 | BM4: =IFERROR(IF(0=LEN(ReferenceData!$BM$4),"",ReferenceData!$BM$4),"") -> 10300.754
A5: =IFERROR(IF(0=LEN(ReferenceData!$A$5),"",ReferenceData!$A$5),"") -> Fixed Investment | B5: =IFERROR(IF(0=LEN(ReferenceData!$B$5),"",ReferenceData!$B$5),"") -> GPDIFXIN Index | C5: =IFERROR(IF(0=LEN(ReferenceData!$C$5),"",ReferenceData!$C$5),"") -> PR005 | D5: =IFERROR(IF(0=LEN(ReferenceData!$D$5),"",ReferenceData!$D$5),"") -> PX_LAST | E5: =IFERROR(IF(0=LEN(ReferenceData!$E$5),"",ReferenceData!$E$5),"") -> Dynamic | F5: =IFERROR(IF(0=LEN(ReferenceData!$F$5),"",ReferenceData!$F$5),"") -> 5402.683 | G5: =IFERROR(IF(0=LEN(ReferenceData!$G$5),"",ReferenceData!$G$5),"") -> 5388.729 | H5: =IFERROR(IF(0=LEN(ReferenceData!$H$5),"",ReferenceData!$H$5),"") -> 5275.129 | I5: =IFERROR(IF(0=LEN(ReferenceData!$I$5),"",ReferenceData!$I$5),"") -> 5269.195 | J5: =IFERROR(IF(0=LEN(ReferenceData!$J$5),"",ReferenceData!$J$5),"") -> 5201.053 | K5: =IFERROR(IF(0=LEN(ReferenceData!$K$5),"",ReferenceData!$K$5),"") -> 5138.499 | L5: =IFERROR(IF(0=LEN(ReferenceData!$L$5),"",ReferenceData!$L$5),"") -> 5046.126 | M5: =IFERROR(IF(0=LEN(ReferenceData!$M$5),"",ReferenceData!$M$5),"") -> 4974.163 | N5: =IFERROR(IF(0=LEN(ReferenceData!$N$5),"",ReferenceData!$N$5),"") -> 4925.655 | O5: =IFERROR(IF(0=LEN(ReferenceData!$O$5),"",ReferenceData!$O$5),"") -> 4826.317 | P5: =IFERROR(IF(0=LEN(ReferenceData!$P$5),"",ReferenceData!$P$5),"") -> 4749.042 | Q5: =IFERROR(IF(0=LEN(ReferenceData!$Q$5),"",ReferenceData!$Q$5),"") -> 4727.803 | R5: =IFERROR(IF(0=LEN(ReferenceData!$R$5),"",ReferenceData!$R$5),"") -> 4669.571 | S5: =IFERROR(IF(0=LEN(ReferenceData!$S$5),"",ReferenceData!$S$5),"") -> 4539.883 | T5: =IFERROR(IF(0=LEN(ReferenceData!$T$5),"",ReferenceData!$T$5),"") -> 4346.39 | U5: =IFERROR(IF(0=LEN(ReferenceData!$U$5),"",ReferenceData!$U$5),"") -> 4231.018 | V5: =IFERROR(IF(0=LEN(ReferenceData!$V$5),"",ReferenceData!$V$5),"") -> 4182.192 | W5: =IFERROR(IF(0=LEN(ReferenceData!$W$5),"",ReferenceData!$W$5),"") -> 4086.717 | X5: =IFERROR(IF(0=LEN(ReferenceData!$X$5),"",ReferenceData!$X$5),"") -> 3968.294 | Y5: =IFERROR(IF(0=LEN(ReferenceData!$Y$5),"",ReferenceData!$Y$5),"") -> 3802.372 | Z5: =IFERROR(IF(0=LEN(ReferenceData!$Z$5),"",ReferenceData!$Z$5),"") -> 3552.634 | AA5: =IFERROR(IF(0=LEN(ReferenceData!$AA$5),"",ReferenceData!$AA$5),"") -> 3841.036 | AB5: =IFERROR(IF(0=LEN(ReferenceData!$AB$5),"",ReferenceData!$AB$5),"") -> 3857.115 | AC5: =IFERROR(IF(0=LEN(ReferenceData!$AC$5),"",ReferenceData!$AC$5),"") -> 3869.365 | AD5: =IFERROR(IF(0=LEN(ReferenceData!$AD$5),"",ReferenceData!$AD$5),"") -> 3820.789 | AE5: =IFERROR(IF(0=LEN(ReferenceData!$AE$5),"",ReferenceData!$AE$5),"") -> 3735.845 | AF5: =IFERROR(IF(0=LEN(ReferenceData!$AF$5),"",ReferenceData!$AF$5),"") -> 3706.704 | AG5: =IFERROR(IF(0=LEN(ReferenceData!$AG$5),"",ReferenceData!$AG$5),"") -> 3690.028 | AH5: =IFERROR(IF(0=LEN(ReferenceData!$AH$5),"",ReferenceData!$AH$5),"") -> 3666.129 | AI5: =IFERROR(IF(0=LEN(ReferenceData!$AI$5),"",ReferenceData!$AI$5),"") -> 3610.589 | AJ5: =IFERROR(IF(0=LEN(ReferenceData!$AJ$5),"",ReferenceData!$AJ$5),"") -> 3530.448 | AK5: =IFERROR(IF(0=LEN(ReferenceData!$AK$5),"",ReferenceData!$AK$5),"") -> 3445.283 | AL5: =IFERROR(IF(0=LEN(ReferenceData!$AL$5),"",ReferenceData!$AL$5),"") -> 3407.44 | AM5: =IFERROR(IF(0=LEN(ReferenceData!$AM$5),"",ReferenceData!$AM$5),"") -> 3356.791 | AN5: =IFERROR(IF(0=LEN(ReferenceData!$AN$5),"",ReferenceData!$AN$5),"") -> 3302.805 | AO5: =IFERROR(IF(0=LEN(ReferenceData!$AO$5),"",ReferenceData!$AO$5),"") -> 3256.247 | AP5: =IFERROR(IF(0=LEN(ReferenceData!$AP$5),"",ReferenceData!$AP$5),"") -> 3215.897 | AQ5: =IFERROR(IF(0=LEN(ReferenceData!$AQ$5),"",ReferenceData!$AQ$5),"") -> 3181.999 | AR5: =IFERROR(IF(0=LEN(ReferenceData!$AR$5),"",ReferenceData!$AR$5),"") -> 3169.729 | AS5: =IFERROR(IF(0=LEN(ReferenceData!$AS$5),"",ReferenceData!$AS$5),"") -> 3176.809 | AT5: =IFERROR(IF(0=LEN(ReferenceData!$AT$5),"",ReferenceData!$AT$5),"") -> 3139.856 | AU5: =IFERROR(IF(0=LEN(ReferenceData!$AU$5),"",ReferenceData!$AU$5),"") -> 3107.041 | AV5: =IFERROR(IF(0=LEN(ReferenceData!$AV$5),"",ReferenceData!$AV$5),"") -> 3086.53 | AW5: =IFERROR(IF(0=LEN(ReferenceData!$AW$5),"",ReferenceData!$AW$5),"") -> 3038.113 | AX5: =IFERROR(IF(0=LEN(ReferenceData!$AX$5),"",ReferenceData!$AX$5),"") -> 2961.343 | AY5: =IFERROR(IF(0=LEN(ReferenceData!$AY$5),"",ReferenceData!$AY$5),"") -> 2870.77 | AZ5: =IFERROR(IF(0=LEN(ReferenceData!$AZ$5),"",ReferenceData!$AZ$5),"") -> 2816.948 | BA5: =IFERROR(IF(0=LEN(ReferenceData!$BA$5),"",ReferenceData!$BA$5),"") -> 2755.705 | BB5: =IFERROR(IF(0=LEN(ReferenceData!$BB$5),"",ReferenceData!$BB$5),"") -> 2697.549 | BC5: =IFERROR(IF(0=LEN(ReferenceData!$BC$5),"",ReferenceData!$BC$5),"") -> 2661.196 | BD5: =IFERROR(IF(0=LEN(ReferenceData!$BD$5),"",ReferenceData!$BD$5),"") -> 2609.548 | BE5: =IFERROR(IF(0=LEN(ReferenceData!$BE$5),"",ReferenceData!$BE$5),"") -> 2559.69 | BF5: =IFERROR(IF(0=LEN(ReferenceData!$BF$5),"",ReferenceData!$BF$5),"") -> 2545.458 | BG5: =IFERROR(IF(0=LEN(ReferenceData!$BG$5),"",ReferenceData!$BG$5),"") -> 2487.473 | BH5: =IFERROR(IF(0=LEN(ReferenceData!$BH$5),"",ReferenceData!$BH$5),"") -> 2400.138 | BI5: =IFERROR(IF(0=LEN(ReferenceData!$BI$5),"",ReferenceData!$BI$5),"") -> 2334.873 | BJ5: =IFERROR(IF(0=LEN(ReferenceData!$BJ$5),"",ReferenceData!$BJ$5),"") -> 2236.305 | BK5: =IFERROR(IF(0=LEN(ReferenceData!$BK$5),"",ReferenceData!$BK$5),"") -> 2173.885 | BL5: =IFERROR(IF(0=LEN(ReferenceData!$BL$5),"",ReferenceData!$BL$5),"") -> 2171.138 | BM5: =IFERROR(IF(0=LEN(ReferenceData!$BM$5),"",ReferenceData!$BM$5),"") -> 2123.598
A6: =IFERROR(IF(0=LEN(ReferenceData!$A$6),"",ReferenceData!$A$6),"") -> Change in Private Inventories | B6: =IFERROR(IF(0=LEN(ReferenceData!$B$6),"",ReferenceData!$B$6),"") -> GDP$PICG Index | C6: =IFERROR(IF(0=LEN(ReferenceData!$C$6),"",ReferenceData!$C$6),"") -> PR005 | D6: =IFERROR(IF(0=LEN(ReferenceData!$D$6),"",ReferenceData!$D$6),"") -> PX_LAST | E6: =IFERROR(IF(0=LEN(ReferenceData!$E$6),"",ReferenceData!$E$6),"") -> Dynamic | F6: =IFERROR(IF(0=LEN(ReferenceData!$F$6),"",ReferenceData!$F$6),"") -> -29.716 | G6: =IFERROR(IF(0=LEN(ReferenceData!$G$6),"",ReferenceData!$G$6),"") -> 206.965 | H6: =IFERROR(IF(0=LEN(ReferenceData!$H$6),"",ReferenceData!$H$6),"") -> 13.634 | I6: =IFERROR(IF(0=LEN(ReferenceData!$I$6),"",ReferenceData!$I$6),"") -> 75.97 | J6: =IFERROR(IF(0=LEN(ReferenceData!$J$6),"",ReferenceData!$J$6),"") -> 96.792 | K6: =IFERROR(IF(0=LEN(ReferenceData!$K$6),"",ReferenceData!$K$6),"") -> 21.404 | L6: =IFERROR(IF(0=LEN(ReferenceData!$L$6),"",ReferenceData!$L$6),"") -> 56.688 | M6: =IFERROR(IF(0=LEN(ReferenceData!$M$6),"",ReferenceData!$M$6),"") -> 89.189 | N6: =IFERROR(IF(0=LEN(ReferenceData!$N$6),"",ReferenceData!$N$6),"") -> 0.01 | O6: =IFERROR(IF(0=LEN(ReferenceData!$O$6),"",ReferenceData!$O$6),"") -> 20.894 | P6: =IFERROR(IF(0=LEN(ReferenceData!$P$6),"",ReferenceData!$P$6),"") -> 162.858 | Q6: =IFERROR(IF(0=LEN(ReferenceData!$Q$6),"",ReferenceData!$Q$6),"") -> 73.821 | R6: =IFERROR(IF(0=LEN(ReferenceData!$R$6),"",ReferenceData!$R$6),"") -> 116.971 | S6: =IFERROR(IF(0=LEN(ReferenceData!$S$6),"",ReferenceData!$S$6),"") -> 244.937 | T6: =IFERROR(IF(0=LEN(ReferenceData!$T$6),"",ReferenceData!$T$6),"") -> 252.794 | U6: =IFERROR(IF(0=LEN(ReferenceData!$U$6),"",ReferenceData!$U$6),"") -> 1.807 | V6: =IFERROR(IF(0=LEN(ReferenceData!$V$6),"",ReferenceData!$V$6),"") -> -164.611 | W6: =IFERROR(IF(0=LEN(ReferenceData!$W$6),"",ReferenceData!$W$6),"") -> -41.219 | X6: =IFERROR(IF(0=LEN(ReferenceData!$X$6),"",ReferenceData!$X$6),"") -> 78.055 | Y6: =IFERROR(IF(0=LEN(ReferenceData!$Y$6),"",ReferenceData!$Y$6),"") -> 98.975 | Z6: =IFERROR(IF(0=LEN(ReferenceData!$Z$6),"",ReferenceData!$Z$6),"") -> -282.276 | AA6: =IFERROR(IF(0=LEN(ReferenceData!$AA$6),"",ReferenceData!$AA$6),"") -> -39.039 | AB6: =IFERROR(IF(0=LEN(ReferenceData!$AB$6),"",ReferenceData!$AB$6),"") -> 23.455 | AC6: =IFERROR(IF(0=LEN(ReferenceData!$AC$6),"",ReferenceData!$AC$6),"") -> 70.234 | AD6: =IFERROR(IF(0=LEN(ReferenceData!$AD$6),"",ReferenceData!$AD$6),"") -> 83.207 | AE6: =IFERROR(IF(0=LEN(ReferenceData!$AE$6),"",ReferenceData!$AE$6),"") -> 114.925 | AF6: =IFERROR(IF(0=LEN(ReferenceData!$AF$6),"",ReferenceData!$AF$6),"") -> 95.324 | AG6: =IFERROR(IF(0=LEN(ReferenceData!$AG$6),"",ReferenceData!$AG$6),"") -> 98.664 | AH6: =IFERROR(IF(0=LEN(ReferenceData!$AH$6),"",ReferenceData!$AH$6),"") -> -3.402 | AI6: =IFERROR(IF(0=LEN(ReferenceData!$AI$6),"",ReferenceData!$AI$6),"") -> 35.045 | AJ6: =IFERROR(IF(0=LEN(ReferenceData!$AJ$6),"",ReferenceData!$AJ$6),"") -> 43.998 | AK6: =IFERROR(IF(0=LEN(ReferenceData!$AK$6),"",ReferenceData!$AK$6),"") -> 54.859 | AL6: =IFERROR(IF(0=LEN(ReferenceData!$AL$6),"",ReferenceData!$AL$6),"") -> 25.528 | AM6: =IFERROR(IF(0=LEN(ReferenceData!$AM$6),"",ReferenceData!$AM$6),"") -> 6.311 | AN6: =IFERROR(IF(0=LEN(ReferenceData!$AN$6),"",ReferenceData!$AN$6),"") -> 58.147 | AO6: =IFERROR(IF(0=LEN(ReferenceData!$AO$6),"",ReferenceData!$AO$6),"") -> 5.324 | AP6: =IFERROR(IF(0=LEN(ReferenceData!$AP$6),"",ReferenceData!$AP$6),"") -> 30.484 | AQ6: =IFERROR(IF(0=LEN(ReferenceData!$AQ$6),"",ReferenceData!$AQ$6),"") -> 62.318 | AR6: =IFERROR(IF(0=LEN(ReferenceData!$AR$6),"",ReferenceData!$AR$6),"") -> 107.15 | AS6: =IFERROR(IF(0=LEN(ReferenceData!$AS$6),"",ReferenceData!$AS$6),"") -> 126.851 | AT6: =IFERROR(IF(0=LEN(ReferenceData!$AT$6),"",ReferenceData!$AT$6),"") -> 151.248 | AU6: =IFERROR(IF(0=LEN(ReferenceData!$AU$6),"",ReferenceData!$AU$6),"") -> 175.242 | AV6: =IFERROR(IF(0=LEN(ReferenceData!$AV$6),"",ReferenceData!$AV$6),"") -> 85.485 | AW6: =IFERROR(IF(0=LEN(ReferenceData!$AW$6),"",ReferenceData!$AW$6),"") -> 103.934 | AX6: =IFERROR(IF(0=LEN(ReferenceData!$AX$6),"",ReferenceData!$AX$6),"") -> 97.753 | AY6: =IFERROR(IF(0=LEN(ReferenceData!$AY$6),"",ReferenceData!$AY$6),"") -> 51.995 | AZ6: =IFERROR(IF(0=LEN(ReferenceData!$AZ$6),"",ReferenceData!$AZ$6),"") -> 117.343 | BA6: =IFERROR(IF(0=LEN(ReferenceData!$BA$6),"",ReferenceData!$BA$6),"") -> 136.649 | BB6: =IFERROR(IF(0=LEN(ReferenceData!$BB$6),"",ReferenceData!$BB$6),"") -> 82.693 | BC6: =IFERROR(IF(0=LEN(ReferenceData!$BC$6),"",ReferenceData!$BC$6),"") -> 85.223 | BD6: =IFERROR(IF(0=LEN(ReferenceData!$BD$6),"",ReferenceData!$BD$6),"") -> 28.734 | BE6: =IFERROR(IF(0=LEN(ReferenceData!$BE$6),"",ReferenceData!$BE$6),"") -> 84.429 | BF6: =IFERROR(IF(0=LEN(ReferenceData!$BF$6),"",ReferenceData!$BF$6),"") -> 91.406 | BG6: =IFERROR(IF(0=LEN(ReferenceData!$BG$6),"",ReferenceData!$BG$6),"") -> 80.278 | BH6: =IFERROR(IF(0=LEN(ReferenceData!$BH$6),"",ReferenceData!$BH$6),"") -> 103.956 | BI6: =IFERROR(IF(0=LEN(ReferenceData!$BI$6),"",ReferenceData!$BI$6),"") -> -12.033 | BJ6: =IFERROR(IF(0=LEN(ReferenceData!$BJ$6),"",ReferenceData!$BJ$6),"") -> 61.047 | BK6: =IFERROR(IF(0=LEN(ReferenceData!$BK$6),"",ReferenceData!$BK$6),"") -> 32.078 | BL6: =IFERROR(IF(0=LEN(ReferenceData!$BL$6),"",ReferenceData!$BL$6),"") -> 67.301 | BM6: =IFERROR(IF(0=LEN(ReferenceData!$BM$6),"",ReferenceData!$BM$6),"") -> 112.897
A7: =IFERROR(IF(0=LEN(ReferenceData!$A$7),"",ReferenceData!$A$7),"") -> Government: Consumption Expenditure | B7: =IFERROR(IF(0=LEN(ReferenceData!$B$7),"",ReferenceData!$B$7),"") -> GCEXCONE Index | C7: =IFERROR(IF(0=LEN(ReferenceData!$C$7),"",ReferenceData!$C$7),"") -> PR005 | D7: =IFERROR(IF(0=LEN(ReferenceData!$D$7),"",ReferenceData!$D$7),"") -> PX_LAST | E7: =IFERROR(IF(0=LEN(ReferenceData!$E$7),"",ReferenceData!$E$7),"") -> Dynamic | F7: =IFERROR(IF(0=LEN(ReferenceData!$F$7),"",ReferenceData!$F$7),"") -> 4054.615 | G7: =IFERROR(IF(0=LEN(ReferenceData!$G$7),"",ReferenceData!$G$7),"") -> 4030.962 | H7: =IFERROR(IF(0=LEN(ReferenceData!$H$7),"",ReferenceData!$H$7),"") -> 3996.878 | I7: =IFERROR(IF(0=LEN(ReferenceData!$I$7),"",ReferenceData!$I$7),"") -> 3947.656 | J7: =IFERROR(IF(0=LEN(ReferenceData!$J$7),"",ReferenceData!$J$7),"") -> 3882.139 | K7: =IFERROR(IF(0=LEN(ReferenceData!$K$7),"",ReferenceData!$K$7),"") -> 3840.088 | L7: =IFERROR(IF(0=LEN(ReferenceData!$L$7),"",ReferenceData!$L$7),"") -> 3781.725 | M7: =IFERROR(IF(0=LEN(ReferenceData!$M$7),"",ReferenceData!$M$7),"") -> 3758.931 | N7: =IFERROR(IF(0=LEN(ReferenceData!$N$7),"",ReferenceData!$N$7),"") -> 3674.318 | O7: =IFERROR(IF(0=LEN(ReferenceData!$O$7),"",ReferenceData!$O$7),"") -> 3680.844 | P7: =IFERROR(IF(0=LEN(ReferenceData!$P$7),"",ReferenceData!$P$7),"") -> 3641.91 | Q7: =IFERROR(IF(0=LEN(ReferenceData!$Q$7),"",ReferenceData!$Q$7),"") -> 3590.272 | R7: =IFERROR(IF(0=LEN(ReferenceData!$R$7),"",ReferenceData!$R$7),"") -> 3560.032 | S7: =IFERROR(IF(0=LEN(ReferenceData!$S$7),"",ReferenceData!$S$7),"") -> 3473.916 | T7: =IFERROR(IF(0=LEN(ReferenceData!$T$7),"",ReferenceData!$T$7),"") -> 3440.748 | U7: =IFERROR(IF(0=LEN(ReferenceData!$U$7),"",ReferenceData!$U$7),"") -> 3386.91 | V7: =IFERROR(IF(0=LEN(ReferenceData!$V$7),"",ReferenceData!$V$7),"") -> 3348.272 | W7: =IFERROR(IF(0=LEN(ReferenceData!$W$7),"",ReferenceData!$W$7),"") -> 3325.207 | X7: =IFERROR(IF(0=LEN(ReferenceData!$X$7),"",ReferenceData!$X$7),"") -> 3195.54 | Y7: =IFERROR(IF(0=LEN(ReferenceData!$Y$7),"",ReferenceData!$Y$7),"") -> 3182.435 | Z7: =IFERROR(IF(0=LEN(ReferenceData!$Z$7),"",ReferenceData!$Z$7),"") -> 3209.423 | AA7: =IFERROR(IF(0=LEN(ReferenceData!$AA$7),"",ReferenceData!$AA$7),"") -> 3136.014 | AB7: =IFERROR(IF(0=LEN(ReferenceData!$AB$7),"",ReferenceData!$AB$7),"") -> 3080.936 | AC7: =IFERROR(IF(0=LEN(ReferenceData!$AC$7),"",ReferenceData!$AC$7),"") -> 3034.139 | AD7: =IFERROR(IF(0=LEN(ReferenceData!$AD$7),"",ReferenceData!$AD$7),"") -> 2994.223 | AE7: =IFERROR(IF(0=LEN(ReferenceData!$AE$7),"",ReferenceData!$AE$7),"") -> 2938.925 | AF7: =IFERROR(IF(0=LEN(ReferenceData!$AF$7),"",ReferenceData!$AF$7),"") -> 2912.96 | AG7: =IFERROR(IF(0=LEN(ReferenceData!$AG$7),"",ReferenceData!$AG$7),"") -> 2885.521 | AH7: =IFERROR(IF(0=LEN(ReferenceData!$AH$7),"",ReferenceData!$AH$7),"") -> 2839.147 | AI7: =IFERROR(IF(0=LEN(ReferenceData!$AI$7),"",ReferenceData!$AI$7),"") -> 2801.299 | AJ7: =IFERROR(IF(0=LEN(ReferenceData!$AJ$7),"",ReferenceData!$AJ$7),"") -> 2761.375 | AK7: =IFERROR(IF(0=LEN(ReferenceData!$AK$7),"",ReferenceData!$AK$7),"") -> 2715.851 | AL7: =IFERROR(IF(0=LEN(ReferenceData!$AL$7),"",ReferenceData!$AL$7),"") -> 2695.724 | AM7: =IFERROR(IF(0=LEN(ReferenceData!$AM$7),"",ReferenceData!$AM$7),"") -> 2689.905 | AN7: =IFERROR(IF(0=LEN(ReferenceData!$AN$7),"",ReferenceData!$AN$7),"") -> 2680.996 | AO7: =IFERROR(IF(0=LEN(ReferenceData!$AO$7),"",ReferenceData!$AO$7),"") -> 2668.281 | AP7: =IFERROR(IF(0=LEN(ReferenceData!$AP$7),"",ReferenceData!$AP$7),"") -> 2642.923 | AQ7: =IFERROR(IF(0=LEN(ReferenceData!$AQ$7),"",ReferenceData!$AQ$7),"") -> 2621.296 | AR7: =IFERROR(IF(0=LEN(ReferenceData!$AR$7),"",ReferenceData!$AR$7),"") -> 2624.356 | AS7: =IFERROR(IF(0=LEN(ReferenceData!$AS$7),"",ReferenceData!$AS$7),"") -> 2615.896 | AT7: =IFERROR(IF(0=LEN(ReferenceData!$AT$7),"",ReferenceData!$AT$7),"") -> 2601.375 | AU7: =IFERROR(IF(0=LEN(ReferenceData!$AU$7),"",ReferenceData!$AU$7),"") -> 2574.327 | AV7: =IFERROR(IF(0=LEN(ReferenceData!$AV$7),"",ReferenceData!$AV$7),"") -> 2571.889 | AW7: =IFERROR(IF(0=LEN(ReferenceData!$AW$7),"",ReferenceData!$AW$7),"") -> 2581.399 | AX7: =IFERROR(IF(0=LEN(ReferenceData!$AX$7),"",ReferenceData!$AX$7),"") -> 2548.426 | AY7: =IFERROR(IF(0=LEN(ReferenceData!$AY$7),"",ReferenceData!$AY$7),"") -> 2547.392 | AZ7: =IFERROR(IF(0=LEN(ReferenceData!$AZ$7),"",ReferenceData!$AZ$7),"") -> 2536.463 | BA7: =IFERROR(IF(0=LEN(ReferenceData!$BA$7),"",ReferenceData!$BA$7),"") -> 2530.734 | BB7: =IFERROR(IF(0=LEN(ReferenceData!$BB$7),"",ReferenceData!$BB$7),"") -> 2531.613 | BC7: =IFERROR(IF(0=LEN(ReferenceData!$BC$7),"",ReferenceData!$BC$7),"") -> 2524.169 | BD7: =IFERROR(IF(0=LEN(ReferenceData!$BD$7),"",ReferenceData!$BD$7),"") -> 2521.55 | BE7: =IFERROR(IF(0=LEN(ReferenceData!$BE$7),"",ReferenceData!$BE$7),"") -> 2519.684 | BF7: =IFERROR(IF(0=LEN(ReferenceData!$BF$7),"",ReferenceData!$BF$7),"") -> 2503.34 | BG7: =IFERROR(IF(0=LEN(ReferenceData!$BG$7),"",ReferenceData!$BG$7),"") -> 2517.184 | BH7: =IFERROR(IF(0=LEN(ReferenceData!$BH$7),"",ReferenceData!$BH$7),"") -> 2495.035 | BI7: =IFERROR(IF(0=LEN(ReferenceData!$BI$7),"",ReferenceData!$BI$7),"") -> 2501.81 | BJ7: =IFERROR(IF(0=LEN(ReferenceData!$BJ$7),"",ReferenceData!$BJ$7),"") -> 2531.982 | BK7: =IFERROR(IF(0=LEN(ReferenceData!$BK$7),"",ReferenceData!$BK$7),"") -> 2516.417 | BL7: =IFERROR(IF(0=LEN(ReferenceData!$BL$7),"",ReferenceData!$BL$7),"") -> 2516.921 | BM7: =IFERROR(IF(0=LEN(ReferenceData!$BM$7),"",ReferenceData!$BM$7),"") -> 2508.885
A8: =IFERROR(IF(0=LEN(ReferenceData!$A$8),"",ReferenceData!$A$8),"") -> Government: Gross Investment | B8: =IFERROR(IF(0=LEN(ReferenceData!$B$8),"",ReferenceData!$B$8),"") -> GCEXGRSS Index | C8: =IFERROR(IF(0=LEN(ReferenceData!$C$8),"",ReferenceData!$C$8),"") -> PR005 | D8: =IFERROR(IF(0=LEN(ReferenceData!$D$8),"",ReferenceData!$D$8),"") -> PX_LAST | E8: =IFERROR(IF(0=LEN(ReferenceData!$E$8),"",ReferenceData!$E$8),"") -> Dynamic | F8: =IFERROR(IF(0=LEN(ReferenceData!$F$8),"",ReferenceData!$F$8),"") -> 1135.041 | G8: =IFERROR(IF(0=LEN(ReferenceData!$G$8),"",ReferenceData!$G$8),"") -> 1118.93 | H8: =IFERROR(IF(0=LEN(ReferenceData!$H$8),"",ReferenceData!$H$8),"") -> 1102.851 | I8: =IFERROR(IF(0=LEN(ReferenceData!$I$8),"",ReferenceData!$I$8),"") -> 1087.352 | J8: =IFERROR(IF(0=LEN(ReferenceData!$J$8),"",ReferenceData!$J$8),"") -> 1060.902 | K8: =IFERROR(IF(0=LEN(ReferenceData!$K$8),"",ReferenceData!$K$8),"") -> 1040.872 | L8: =IFERROR(IF(0=LEN(ReferenceData!$L$8),"",ReferenceData!$L$8),"") -> 1033.426 | M8: =IFERROR(IF(0=LEN(ReferenceData!$M$8),"",ReferenceData!$M$8),"") -> 997.517 | N8: =IFERROR(IF(0=LEN(ReferenceData!$N$8),"",ReferenceData!$N$8),"") -> 971.587 | O8: =IFERROR(IF(0=LEN(ReferenceData!$O$8),"",ReferenceData!$O$8),"") -> 943.742 | P8: =IFERROR(IF(0=LEN(ReferenceData!$P$8),"",ReferenceData!$P$8),"") -> 922.882 | Q8: =IFERROR(IF(0=LEN(ReferenceData!$Q$8),"",ReferenceData!$Q$8),"") -> 889.778 | R8: =IFERROR(IF(0=LEN(ReferenceData!$R$8),"",ReferenceData!$R$8),"") -> 877.577 | S8: =IFERROR(IF(0=LEN(ReferenceData!$S$8),"",ReferenceData!$S$8),"") -> 858.694 | T8: =IFERROR(IF(0=LEN(ReferenceData!$T$8),"",ReferenceData!$T$8),"") -> 841.57 | U8: =IFERROR(IF(0=LEN(ReferenceData!$U$8),"",ReferenceData!$U$8),"") -> 827.06 | V8: =IFERROR(IF(0=LEN(ReferenceData!$V$8),"",ReferenceData!$V$8),"") -> 821.744 | W8: =IFERROR(IF(0=LEN(ReferenceData!$W$8),"",ReferenceData!$W$8),"") -> 822.419 | X8: =IFERROR(IF(0=LEN(ReferenceData!$X$8),"",ReferenceData!$X$8),"") -> 832.455 | Y8: =IFERROR(IF(0=LEN(ReferenceData!$Y$8),"",ReferenceData!$Y$8),"") -> 819.135 | Z8: =IFERROR(IF(0=LEN(ReferenceData!$Z$8),"",ReferenceData!$Z$8),"") -> 816.551 | AA8: =IFERROR(IF(0=LEN(ReferenceData!$AA$8),"",ReferenceData!$AA$8),"") -> 806.998 | AB8: =IFERROR(IF(0=LEN(ReferenceData!$AB$8),"",ReferenceData!$AB$8),"") -> 784.032 | AC8: =IFERROR(IF(0=LEN(ReferenceData!$AC$8),"",ReferenceData!$AC$8),"") -> 780.698 | AD8: =IFERROR(IF(0=LEN(ReferenceData!$AD$8),"",ReferenceData!$AD$8),"") -> 767.02 | AE8: =IFERROR(IF(0=LEN(ReferenceData!$AE$8),"",ReferenceData!$AE$8),"") -> 764.009 | AF8: =IFERROR(IF(0=LEN(ReferenceData!$AF$8),"",ReferenceData!$AF$8),"") -> 737.888 | AG8: =IFERROR(IF(0=LEN(ReferenceData!$AG$8),"",ReferenceData!$AG$8),"") -> 740.565 | AH8: =IFERROR(IF(0=LEN(ReferenceData!$AH$8),"",ReferenceData!$AH$8),"") -> 731.567 | AI8: =IFERROR(IF(0=LEN(ReferenceData!$AI$8),"",ReferenceData!$AI$8),"") -> 712.577 | AJ8: =IFERROR(IF(0=LEN(ReferenceData!$AJ$8),"",ReferenceData!$AJ$8),"") -> 704.762 | AK8: =IFERROR(IF(0=LEN(ReferenceData!$AK$8),"",ReferenceData!$AK$8),"") -> 683.035 | AL8: =IFERROR(IF(0=LEN(ReferenceData!$AL$8),"",ReferenceData!$AL$8),"") -> 674.72 | AM8: =IFERROR(IF(0=LEN(ReferenceData!$AM$8),"",ReferenceData!$AM$8),"") -> 663.191 | AN8: =IFERROR(IF(0=LEN(ReferenceData!$AN$8),"",ReferenceData!$AN$8),"") -> 656.249 | AO8: =IFERROR(IF(0=LEN(ReferenceData!$AO$8),"",ReferenceData!$AO$8),"") -> 646.89 | AP8: =IFERROR(IF(0=LEN(ReferenceData!$AP$8),"",ReferenceData!$AP$8),"") -> 646.644 | AQ8: =IFERROR(IF(0=LEN(ReferenceData!$AQ$8),"",ReferenceData!$AQ$8),"") -> 648.845 | AR8: =IFERROR(IF(0=LEN(ReferenceData!$AR$8),"",ReferenceData!$AR$8),"") -> 633.787 | AS8: =IFERROR(IF(0=LEN(ReferenceData!$AS$8),"",ReferenceData!$AS$8),"") -> 637.658 | AT8: =IFERROR(IF(0=LEN(ReferenceData!$AT$8),"",ReferenceData!$AT$8),"") -> 632.692 | AU8: =IFERROR(IF(0=LEN(ReferenceData!$AU$8),"",ReferenceData!$AU$8),"") -> 613.588 | AV8: =IFERROR(IF(0=LEN(ReferenceData!$AV$8),"",ReferenceData!$AV$8),"") -> 617.364 | AW8: =IFERROR(IF(0=LEN(ReferenceData!$AW$8),"",ReferenceData!$AW$8),"") -> 610.35 | AX8: =IFERROR(IF(0=LEN(ReferenceData!$AX$8),"",ReferenceData!$AX$8),"") -> 605.94 | AY8: =IFERROR(IF(0=LEN(ReferenceData!$AY$8),"",ReferenceData!$AY$8),"") -> 591.669 | AZ8: =IFERROR(IF(0=LEN(ReferenceData!$AZ$8),"",ReferenceData!$AZ$8),"") -> 604.054 | BA8: =IFERROR(IF(0=LEN(ReferenceData!$BA$8),"",ReferenceData!$BA$8),"") -> 604.458 | BB8: =IFERROR(IF(0=LEN(ReferenceData!$BB$8),"",ReferenceData!$BB$8),"") -> 599.53 | BC8: =IFERROR(IF(0=LEN(ReferenceData!$BC$8),"",ReferenceData!$BC$8),"") -> 599.285 | BD8: =IFERROR(IF(0=LEN(ReferenceData!$BD$8),"",ReferenceData!$BD$8),"") -> 610.758 | BE8: =IFERROR(IF(0=LEN(ReferenceData!$BE$8),"",ReferenceData!$BE$8),"") -> 619.428 | BF8: =IFERROR(IF(0=LEN(ReferenceData!$BF$8),"",ReferenceData!$BF$8),"") -> 627.098 | BG8: =IFERROR(IF(0=LEN(ReferenceData!$BG$8),"",ReferenceData!$BG$8),"") -> 626.841 | BH8: =IFERROR(IF(0=LEN(ReferenceData!$BH$8),"",ReferenceData!$BH$8),"") -> 635.731 | BI8: =IFERROR(IF(0=LEN(ReferenceData!$BI$8),"",ReferenceData!$BI$8),"") -> 635.112 | BJ8: =IFERROR(IF(0=LEN(ReferenceData!$BJ$8),"",ReferenceData!$BJ$8),"") -> 636.279 | BK8: =IFERROR(IF(0=LEN(ReferenceData!$BK$8),"",ReferenceData!$BK$8),"") -> 639.351 | BL8: =IFERROR(IF(0=LEN(ReferenceData!$BL$8),"",ReferenceData!$BL$8),"") -> 647.396 | BM8: =IFERROR(IF(0=LEN(ReferenceData!$BM$8),"",ReferenceData!$BM$8),"") -> 649.416
A9: =IFERROR(IF(0=LEN(ReferenceData!$A$9),"",ReferenceData!$A$9),"") -> Exports | B9: =IFERROR(IF(0=LEN(ReferenceData!$B$9),"",ReferenceData!$B$9),"") -> GDP$EXP Index | C9: =IFERROR(IF(0=LEN(ReferenceData!$C$9),"",ReferenceData!$C$9),"") -> PR005 | D9: =IFERROR(IF(0=LEN(ReferenceData!$D$9),"",ReferenceData!$D$9),"") -> PX_LAST | E9: =IFERROR(IF(0=LEN(ReferenceData!$E$9),"",ReferenceData!$E$9),"") -> Dynamic | F9: =IFERROR(IF(0=LEN(ReferenceData!$F$9),"",ReferenceData!$F$9),"") -> 3241.946 | G9: =IFERROR(IF(0=LEN(ReferenceData!$G$9),"",ReferenceData!$G$9),"") -> 3266.413 | H9: =IFERROR(IF(0=LEN(ReferenceData!$H$9),"",ReferenceData!$H$9),"") -> 3220.929 | I9: =IFERROR(IF(0=LEN(ReferenceData!$I$9),"",ReferenceData!$I$9),"") -> 3220.292 | J9: =IFERROR(IF(0=LEN(ReferenceData!$J$9),"",ReferenceData!$J$9),"") -> 3154.321 | K9: =IFERROR(IF(0=LEN(ReferenceData!$K$9),"",ReferenceData!$K$9),"") -> 3125.421 | L9: =IFERROR(IF(0=LEN(ReferenceData!$L$9),"",ReferenceData!$L$9),"") -> 3091.748 | M9: =IFERROR(IF(0=LEN(ReferenceData!$M$9),"",ReferenceData!$M$9),"") -> 3062.041 | N9: =IFERROR(IF(0=LEN(ReferenceData!$N$9),"",ReferenceData!$N$9),"") -> 2995.524 | O9: =IFERROR(IF(0=LEN(ReferenceData!$O$9),"",ReferenceData!$O$9),"") -> 3060.562 | P9: =IFERROR(IF(0=LEN(ReferenceData!$P$9),"",ReferenceData!$P$9),"") -> 3046.718 | Q9: =IFERROR(IF(0=LEN(ReferenceData!$Q$9),"",ReferenceData!$Q$9),"") -> 3102.55 | R9: =IFERROR(IF(0=LEN(ReferenceData!$R$9),"",ReferenceData!$R$9),"") -> 3071.551 | S9: =IFERROR(IF(0=LEN(ReferenceData!$S$9),"",ReferenceData!$S$9),"") -> 2848.698 | T9: =IFERROR(IF(0=LEN(ReferenceData!$T$9),"",ReferenceData!$T$9),"") -> 2765.36 | U9: =IFERROR(IF(0=LEN(ReferenceData!$U$9),"",ReferenceData!$U$9),"") -> 2570.103 | V9: =IFERROR(IF(0=LEN(ReferenceData!$V$9),"",ReferenceData!$V$9),"") -> 2505.032 | W9: =IFERROR(IF(0=LEN(ReferenceData!$W$9),"",ReferenceData!$W$9),"") -> 2381.224 | X9: =IFERROR(IF(0=LEN(ReferenceData!$X$9),"",ReferenceData!$X$9),"") -> 2268.891 | Y9: =IFERROR(IF(0=LEN(ReferenceData!$Y$9),"",ReferenceData!$Y$9),"") -> 2105.083 | Z9: =IFERROR(IF(0=LEN(ReferenceData!$Z$9),"",ReferenceData!$Z$9),"") -> 1814.401 | AA9: =IFERROR(IF(0=LEN(ReferenceData!$AA$9),"",ReferenceData!$AA$9),"") -> 2416.181 | AB9: =IFERROR(IF(0=LEN(ReferenceData!$AB$9),"",ReferenceData!$AB$9),"") -> 2537.466 | AC9: =IFERROR(IF(0=LEN(ReferenceData!$AC$9),"",ReferenceData!$AC$9),"") -> 2532.405 | AD9: =IFERROR(IF(0=LEN(ReferenceData!$AD$9),"",ReferenceData!$AD$9),"") -> 2547.448 | AE9: =IFERROR(IF(0=LEN(ReferenceData!$AE$9),"",ReferenceData!$AE$9),"") -> 2540.244 | AF9: =IFERROR(IF(0=LEN(ReferenceData!$AF$9),"",ReferenceData!$AF$9),"") -> 2537.415 | AG9: =IFERROR(IF(0=LEN(ReferenceData!$AG$9),"",ReferenceData!$AG$9),"") -> 2535.501 | AH9: =IFERROR(IF(0=LEN(ReferenceData!$AH$9),"",ReferenceData!$AH$9),"") -> 2562.172 | AI9: =IFERROR(IF(0=LEN(ReferenceData!$AI$9),"",ReferenceData!$AI$9),"") -> 2517.268 | AJ9: =IFERROR(IF(0=LEN(ReferenceData!$AJ$9),"",ReferenceData!$AJ$9),"") -> 2479.107 | AK9: =IFERROR(IF(0=LEN(ReferenceData!$AK$9),"",ReferenceData!$AK$9),"") -> 2384.524 | AL9: =IFERROR(IF(0=LEN(ReferenceData!$AL$9),"",ReferenceData!$AL$9),"") -> 2349.681 | AM9: =IFERROR(IF(0=LEN(ReferenceData!$AM$9),"",ReferenceData!$AM$9),"") -> 2339.728 | AN9: =IFERROR(IF(0=LEN(ReferenceData!$AN$9),"",ReferenceData!$AN$9),"") -> 2268.339 | AO9: =IFERROR(IF(0=LEN(ReferenceData!$AO$9),"",ReferenceData!$AO$9),"") -> 2270 | AP9: =IFERROR(IF(0=LEN(ReferenceData!$AP$9),"",ReferenceData!$AP$9),"") -> 2221.936 | AQ9: =IFERROR(IF(0=LEN(ReferenceData!$AQ$9),"",ReferenceData!$AQ$9),"") -> 2181.957 | AR9: =IFERROR(IF(0=LEN(ReferenceData!$AR$9),"",ReferenceData!$AR$9),"") -> 2222.279 | AS9: =IFERROR(IF(0=LEN(ReferenceData!$AS$9),"",ReferenceData!$AS$9),"") -> 2260.724 | AT9: =IFERROR(IF(0=LEN(ReferenceData!$AT$9),"",ReferenceData!$AT$9),"") -> 2300.441 | AU9: =IFERROR(IF(0=LEN(ReferenceData!$AU$9),"",ReferenceData!$AU$9),"") -> 2299.045 | AV9: =IFERROR(IF(0=LEN(ReferenceData!$AV$9),"",ReferenceData!$AV$9),"") -> 2376.218 | AW9: =IFERROR(IF(0=LEN(ReferenceData!$AW$9),"",ReferenceData!$AW$9),"") -> 2399.191 | AX9: =IFERROR(IF(0=LEN(ReferenceData!$AX$9),"",ReferenceData!$AX$9),"") -> 2395.168 | AY9: =IFERROR(IF(0=LEN(ReferenceData!$AY$9),"",ReferenceData!$AY$9),"") -> 2343.602 | AZ9: =IFERROR(IF(0=LEN(ReferenceData!$AZ$9),"",ReferenceData!$AZ$9),"") -> 2349.24 | BA9: =IFERROR(IF(0=LEN(ReferenceData!$BA$9),"",ReferenceData!$BA$9),"") -> 2285.116 | BB9: =IFERROR(IF(0=LEN(ReferenceData!$BB$9),"",ReferenceData!$BB$9),"") -> 2261.403 | BC9: =IFERROR(IF(0=LEN(ReferenceData!$BC$9),"",ReferenceData!$BC$9),"") -> 2255.929 | BD9: =IFERROR(IF(0=LEN(ReferenceData!$BD$9),"",ReferenceData!$BD$9),"") -> 2237.498 | BE9: =IFERROR(IF(0=LEN(ReferenceData!$BE$9),"",ReferenceData!$BE$9),"") -> 2227.734 | BF9: =IFERROR(IF(0=LEN(ReferenceData!$BF$9),"",ReferenceData!$BF$9),"") -> 2215.586 | BG9: =IFERROR(IF(0=LEN(ReferenceData!$BG$9),"",ReferenceData!$BG$9),"") -> 2189.981 | BH9: =IFERROR(IF(0=LEN(ReferenceData!$BH$9),"",ReferenceData!$BH$9),"") -> 2150.123 | BI9: =IFERROR(IF(0=LEN(ReferenceData!$BI$9),"",ReferenceData!$BI$9),"") -> 2156.793 | BJ9: =IFERROR(IF(0=LEN(ReferenceData!$BJ$9),"",ReferenceData!$BJ$9),"") -> 2116.132 | BK9: =IFERROR(IF(0=LEN(ReferenceData!$BK$9),"",ReferenceData!$BK$9),"") -> 2040.407 | BL9: =IFERROR(IF(0=LEN(ReferenceData!$BL$9),"",ReferenceData!$BL$9),"") -> 1972.116 | BM9: =IFERROR(IF(0=LEN(ReferenceData!$BM$9),"",ReferenceData!$BM$9),"") -> 1877.253
A10: =IFERROR(IF(0=LEN(ReferenceData!$A$10),"",ReferenceData!$A$10),"") -> Imports | B10: =IFERROR(IF(0=LEN(ReferenceData!$B$10),"",ReferenceData!$B$10),"") -> GDP$IMP Index | C10: =IFERROR(IF(0=LEN(ReferenceData!$C$10),"",ReferenceData!$C$10),"") -> PR005 | D10: =IFERROR(IF(0=LEN(ReferenceData!$D$10),"",ReferenceData!$D$10),"") -> PX_LAST | E10: =IFERROR(IF(0=LEN(ReferenceData!$E$10),"",ReferenceData!$E$10),"") -> Dynamic | F10: =IFERROR(IF(0=LEN(ReferenceData!$F$10),"",ReferenceData!$F$10),"") -> 4114.33 | G10: =IFERROR(IF(0=LEN(ReferenceData!$G$10),"",ReferenceData!$G$10),"") -> 4511.554 | H10: =IFERROR(IF(0=LEN(ReferenceData!$H$10),"",ReferenceData!$H$10),"") -> 4141.013 | I10: =IFERROR(IF(0=LEN(ReferenceData!$I$10),"",ReferenceData!$I$10),"") -> 4163.975 | J10: =IFERROR(IF(0=LEN(ReferenceData!$J$10),"",ReferenceData!$J$10),"") -> 4061.192 | K10: =IFERROR(IF(0=LEN(ReferenceData!$K$10),"",ReferenceData!$K$10),"") -> 3966.989 | L10: =IFERROR(IF(0=LEN(ReferenceData!$L$10),"",ReferenceData!$L$10),"") -> 3882.899 | M10: =IFERROR(IF(0=LEN(ReferenceData!$M$10),"",ReferenceData!$M$10),"") -> 3843.132 | N10: =IFERROR(IF(0=LEN(ReferenceData!$N$10),"",ReferenceData!$N$10),"") -> 3799.003 | O10: =IFERROR(IF(0=LEN(ReferenceData!$O$10),"",ReferenceData!$O$10),"") -> 3874.21 | P10: =IFERROR(IF(0=LEN(ReferenceData!$P$10),"",ReferenceData!$P$10),"") -> 3897.402 | Q10: =IFERROR(IF(0=LEN(ReferenceData!$Q$10),"",ReferenceData!$Q$10),"") -> 3988.447 | R10: =IFERROR(IF(0=LEN(ReferenceData!$R$10),"",ReferenceData!$R$10),"") -> 4093.663 | S10: =IFERROR(IF(0=LEN(ReferenceData!$S$10),"",ReferenceData!$S$10),"") -> 3925.742 | T10: =IFERROR(IF(0=LEN(ReferenceData!$T$10),"",ReferenceData!$T$10),"") -> 3685.956 | U10: =IFERROR(IF(0=LEN(ReferenceData!$U$10),"",ReferenceData!$U$10),"") -> 3458.783 | V10: =IFERROR(IF(0=LEN(ReferenceData!$V$10),"",ReferenceData!$V$10),"") -> 3340.114 | W10: =IFERROR(IF(0=LEN(ReferenceData!$W$10),"",ReferenceData!$W$10),"") -> 3176.982 | X10: =IFERROR(IF(0=LEN(ReferenceData!$X$10),"",ReferenceData!$X$10),"") -> 3027.199 | Y10: =IFERROR(IF(0=LEN(ReferenceData!$Y$10),"",ReferenceData!$Y$10),"") -> 2801.482 | Z10: =IFERROR(IF(0=LEN(ReferenceData!$Z$10),"",ReferenceData!$Z$10),"") -> 2350.926 | AA10: =IFERROR(IF(0=LEN(ReferenceData!$AA$10),"",ReferenceData!$AA$10),"") -> 2929.759 | AB10: =IFERROR(IF(0=LEN(ReferenceData!$AB$10),"",ReferenceData!$AB$10),"") -> 3050.824 | AC10: =IFERROR(IF(0=LEN(ReferenceData!$AC$10),"",ReferenceData!$AC$10),"") -> 3117.952 | AD10: =IFERROR(IF(0=LEN(ReferenceData!$AD$10),"",ReferenceData!$AD$10),"") -> 3165.41 | AE10: =IFERROR(IF(0=LEN(ReferenceData!$AE$10),"",ReferenceData!$AE$10),"") -> 3132.539 | AF10: =IFERROR(IF(0=LEN(ReferenceData!$AF$10),"",ReferenceData!$AF$10),"") -> 3171.622 | AG10: =IFERROR(IF(0=LEN(ReferenceData!$AG$10),"",ReferenceData!$AG$10),"") -> 3153.747 | AH10: =IFERROR(IF(0=LEN(ReferenceData!$AH$10),"",ReferenceData!$AH$10),"") -> 3105.995 | AI10: =IFERROR(IF(0=LEN(ReferenceData!$AI$10),"",ReferenceData!$AI$10),"") -> 3093.299 | AJ10: =IFERROR(IF(0=LEN(ReferenceData!$AJ$10),"",ReferenceData!$AJ$10),"") -> 3034.004 | AK10: =IFERROR(IF(0=LEN(ReferenceData!$AK$10),"",ReferenceData!$AK$10),"") -> 2916.022 | AL10: =IFERROR(IF(0=LEN(ReferenceData!$AL$10),"",ReferenceData!$AL$10),"") -> 2903.18 | AM10: =IFERROR(IF(0=LEN(ReferenceData!$AM$10),"",ReferenceData!$AM$10),"") -> 2873.148 | AN10: =IFERROR(IF(0=LEN(ReferenceData!$AN$10),"",ReferenceData!$AN$10),"") -> 2799.145 | AO10: =IFERROR(IF(0=LEN(ReferenceData!$AO$10),"",ReferenceData!$AO$10),"") -> 2751.229 | AP10: =IFERROR(IF(0=LEN(ReferenceData!$AP$10),"",ReferenceData!$AP$10),"") -> 2711.306 | AQ10: =IFERROR(IF(0=LEN(ReferenceData!$AQ$10),"",ReferenceData!$AQ$10),"") -> 2693.639 | AR10: =IFERROR(IF(0=LEN(ReferenceData!$AR$10),"",ReferenceData!$AR$10),"") -> 2745.517 | AS10: =IFERROR(IF(0=LEN(ReferenceData!$AS$10),"",ReferenceData!$AS$10),"") -> 2798.806 | AT10: =IFERROR(IF(0=LEN(ReferenceData!$AT$10),"",ReferenceData!$AT$10),"") -> 2809.968 | AU10: =IFERROR(IF(0=LEN(ReferenceData!$AU$10),"",ReferenceData!$AU$10),"") -> 2825.476 | AV10: =IFERROR(IF(0=LEN(ReferenceData!$AV$10),"",ReferenceData!$AV$10),"") -> 2906.969 | AW10: =IFERROR(IF(0=LEN(ReferenceData!$AW$10),"",ReferenceData!$AW$10),"") -> 2888.549 | AX10: =IFERROR(IF(0=LEN(ReferenceData!$AX$10),"",ReferenceData!$AX$10),"") -> 2900.572 | AY10: =IFERROR(IF(0=LEN(ReferenceData!$AY$10),"",ReferenceData!$AY$10),"") -> 2853.69 | AZ10: =IFERROR(IF(0=LEN(ReferenceData!$AZ$10),"",ReferenceData!$AZ$10),"") -> 2783.259 | BA10: =IFERROR(IF(0=LEN(ReferenceData!$BA$10),"",ReferenceData!$BA$10),"") -> 2767.183 | BB10: =IFERROR(IF(0=LEN(ReferenceData!$BB$10),"",ReferenceData!$BB$10),"") -> 2759.783 | BC10: =IFERROR(IF(0=LEN(ReferenceData!$BC$10),"",ReferenceData!$BC$10),"") -> 2755.277 | BD10: =IFERROR(IF(0=LEN(ReferenceData!$BD$10),"",ReferenceData!$BD$10),"") -> 2753.373 | BE10: =IFERROR(IF(0=LEN(ReferenceData!$BE$10),"",ReferenceData!$BE$10),"") -> 2750.817 | BF10: =IFERROR(IF(0=LEN(ReferenceData!$BF$10),"",ReferenceData!$BF$10),"") -> 2780.827 | BG10: =IFERROR(IF(0=LEN(ReferenceData!$BG$10),"",ReferenceData!$BG$10),"") -> 2792.253 | BH10: =IFERROR(IF(0=LEN(ReferenceData!$BH$10),"",ReferenceData!$BH$10),"") -> 2751.911 | BI10: =IFERROR(IF(0=LEN(ReferenceData!$BI$10),"",ReferenceData!$BI$10),"") -> 2723.903 | BJ10: =IFERROR(IF(0=LEN(ReferenceData!$BJ$10),"",ReferenceData!$BJ$10),"") -> 2697.224 | BK10: =IFERROR(IF(0=LEN(ReferenceData!$BK$10),"",ReferenceData!$BK$10),"") -> 2608.884 | BL10: =IFERROR(IF(0=LEN(ReferenceData!$BL$10),"",ReferenceData!$BL$10),"") -> 2495.702 | BM10: =IFERROR(IF(0=LEN(ReferenceData!$BM$10),"",ReferenceData!$BM$10),"") -> 2431.195
A11: =IFERROR(IF(0=LEN(ReferenceData!$A$11),"",ReferenceData!$A$11),"") -> Western Europe (Bil.) - Euro Area (EUR) | B11: =IFERROR(IF(0=LEN(ReferenceData!$B$11),"",ReferenceData!$B$11),"") -> EUGDEMU Index | C11: =IFERROR(IF(0=LEN(ReferenceData!$C$11),"",ReferenceData!$C$11),"") | D11: =IFERROR(IF(0=LEN(ReferenceData!$D$11),"",ReferenceData!$D$11),"") | E11: =IFERROR(IF(0=LEN(ReferenceData!$E$11),"",ReferenceData!$E$11),"") -> Expression | F11: =IFERROR(IF(0=LEN(ReferenceData!$F$11),"",ReferenceData!$F$11),"") | G11: =IFERROR(IF(0=LEN(ReferenceData!$G$11),"",ReferenceData!$G$11),"") -> 3885.9885 | H11: =IFERROR(IF(0=LEN(ReferenceData!$H$11),"",ReferenceData!$H$11),"") -> 3852.702 | I11: =IFERROR(IF(0=LEN(ReferenceData!$I$11),"",ReferenceData!$I$11),"") -> 3807.5193 | J11: =IFERROR(IF(0=LEN(ReferenceData!$J$11),"",ReferenceData!$J$11),"") -> 3772.4073 | K11: =IFERROR(IF(0=LEN(ReferenceData!$K$11),"",ReferenceData!$K$11),"") -> 3743.2065 | L11: =IFERROR(IF(0=LEN(ReferenceData!$L$11),"",ReferenceData!$L$11),"") -> 3708.097 | M11: =IFERROR(IF(0=LEN(ReferenceData!$M$11),"",ReferenceData!$M$11),"") -> 3667.9545 | N11: =IFERROR(IF(0=LEN(ReferenceData!$N$11),"",ReferenceData!$N$11),"") -> 3640.3645 | O11: =IFERROR(IF(0=LEN(ReferenceData!$O$11),"",ReferenceData!$O$11),"") -> 3592.8278 | P11: =IFERROR(IF(0=LEN(ReferenceData!$P$11),"",ReferenceData!$P$11),"") -> 3527.2652 | Q11: =IFERROR(IF(0=LEN(ReferenceData!$Q$11),"",ReferenceData!$Q$11),"") -> 3460.664 | R11: =IFERROR(IF(0=LEN(ReferenceData!$R$11),"",ReferenceData!$R$11),"") -> 3399.6503 | S11: =IFERROR(IF(0=LEN(ReferenceData!$S$11),"",ReferenceData!$S$11),"") -> 3326.8777 | T11: =IFERROR(IF(0=LEN(ReferenceData!$T$11),"",ReferenceData!$T$11),"") -> 3263.3072 | U11: =IFERROR(IF(0=LEN(ReferenceData!$U$11),"",ReferenceData!$U$11),"") -> 3199.6137 | V11: =IFERROR(IF(0=LEN(ReferenceData!$V$11),"",ReferenceData!$V$11),"") -> 3105.8169 | W11: =IFERROR(IF(0=LEN(ReferenceData!$W$11),"",ReferenceData!$W$11),"") -> 3028.6187 | X11: =IFERROR(IF(0=LEN(ReferenceData!$X$11),"",ReferenceData!$X$11),"") -> 2992.5549 | Y11: =IFERROR(IF(0=LEN(ReferenceData!$Y$11),"",ReferenceData!$Y$11),"") -> 2958.6418 | Z11: =IFERROR(IF(0=LEN(ReferenceData!$Z$11),"",ReferenceData!$Z$11),"") -> 2678.0275 | AA11: =IFERROR(IF(0=LEN(ReferenceData!$AA$11),"",ReferenceData!$AA$11),"") -> 2976.8248 | AB11: =IFERROR(IF(0=LEN(ReferenceData!$AB$11),"",ReferenceData!$AB$11),"") -> 3065.2432 | AC11: =IFERROR(IF(0=LEN(ReferenceData!$AC$11),"",ReferenceData!$AC$11),"") -> 3048.1265 | AD11: =IFERROR(IF(0=LEN(ReferenceData!$AD$11),"",ReferenceData!$AD$11),"") -> 3027.6762 | AE11: =IFERROR(IF(0=LEN(ReferenceData!$AE$11),"",ReferenceData!$AE$11),"") -> 3006.5916 | AF11: =IFERROR(IF(0=LEN(ReferenceData!$AF$11),"",ReferenceData!$AF$11),"") -> 2975.5678 | AG11: =IFERROR(IF(0=LEN(ReferenceData!$AG$11),"",ReferenceData!$AG$11),"") -> 2943.8759 | AH11: =IFERROR(IF(0=LEN(ReferenceData!$AH$11),"",ReferenceData!$AH$11),"") -> 2926.8874 | AI11: =IFERROR(IF(0=LEN(ReferenceData!$AI$11),"",ReferenceData!$AI$11),"") -> 2904.8177 | AJ11: =IFERROR(IF(0=LEN(ReferenceData!$AJ$11),"",ReferenceData!$AJ$11),"") -> 2889.9533 | AK11: =IFERROR(IF(0=LEN(ReferenceData!$AK$11),"",ReferenceData!$AK$11),"") -> 2856.9899 | AL11: =IFERROR(IF(0=LEN(ReferenceData!$AL$11),"",ReferenceData!$AL$11),"") -> 2830.3412 | AM11: =IFERROR(IF(0=LEN(ReferenceData!$AM$11),"",ReferenceData!$AM$11),"") -> 2798.8087 | AN11: =IFERROR(IF(0=LEN(ReferenceData!$AN$11),"",ReferenceData!$AN$11),"") -> 2766.2286 | AO11: =IFERROR(IF(0=LEN(ReferenceData!$AO$11),"",ReferenceData!$AO$11),"") -> 2743.7322 | AP11: =IFERROR(IF(0=LEN(ReferenceData!$AP$11),"",ReferenceData!$AP$11),"") -> 2723.8741 | AQ11: =IFERROR(IF(0=LEN(ReferenceData!$AQ$11),"",ReferenceData!$AQ$11),"") -> 2713.3994 | AR11: =IFERROR(IF(0=LEN(ReferenceData!$AR$11),"",ReferenceData!$AR$11),"") -> 2693.0786 | AS11: =IFERROR(IF(0=LEN(ReferenceData!$AS$11),"",ReferenceData!$AS$11),"") -> 2676.4627 | AT11: =IFERROR(IF(0=LEN(ReferenceData!$AT$11),"",ReferenceData!$AT$11),"") -> 2656.2975 | AU11: =IFERROR(IF(0=LEN(ReferenceData!$AU$11),"",ReferenceData!$AU$11),"") -> 2633.1903 | AV11: =IFERROR(IF(0=LEN(ReferenceData!$AV$11),"",ReferenceData!$AV$11),"") -> 2601.3535 | AW11: =IFERROR(IF(0=LEN(ReferenceData!$AW$11),"",ReferenceData!$AW$11),"") -> 2583.9663 | AX11: =IFERROR(IF(0=LEN(ReferenceData!$AX$11),"",ReferenceData!$AX$11),"") -> 2567.4388 | AY11: =IFERROR(IF(0=LEN(ReferenceData!$AY$11),"",ReferenceData!$AY$11),"") -> 2555.6487 | AZ11: =IFERROR(IF(0=LEN(ReferenceData!$AZ$11),"",ReferenceData!$AZ$11),"") -> 2532.5553 | BA11: =IFERROR(IF(0=LEN(ReferenceData!$BA$11),"",ReferenceData!$BA$11),"") -> 2525.3384 | BB11: =IFERROR(IF(0=LEN(ReferenceData!$BB$11),"",ReferenceData!$BB$11),"") -> 2514.883 | BC11: =IFERROR(IF(0=LEN(ReferenceData!$BC$11),"",ReferenceData!$BC$11),"") -> 2492.6291 | BD11: =IFERROR(IF(0=LEN(ReferenceData!$BD$11),"",ReferenceData!$BD$11),"") -> 2486.918 | BE11: =IFERROR(IF(0=LEN(ReferenceData!$BE$11),"",ReferenceData!$BE$11),"") -> 2492.9426 | BF11: =IFERROR(IF(0=LEN(ReferenceData!$BF$11),"",ReferenceData!$BF$11),"") -> 2485.9026 | BG11: =IFERROR(IF(0=LEN(ReferenceData!$BG$11),"",ReferenceData!$BG$11),"") -> 2487.869 | BH11: =IFERROR(IF(0=LEN(ReferenceData!$BH$11),"",ReferenceData!$BH$11),"") -> 2484.4287 | BI11: =IFERROR(IF(0=LEN(ReferenceData!$BI$11),"",ReferenceData!$BI$11),"") -> 2485.1313 | BJ11: =IFERROR(IF(0=LEN(ReferenceData!$BJ$11),"",ReferenceData!$BJ$11),"") -> 2476.8837 | BK11: =IFERROR(IF(0=LEN(ReferenceData!$BK$11),"",ReferenceData!$BK$11),"") -> 2472.0133 | BL11: =IFERROR(IF(0=LEN(ReferenceData!$BL$11),"",ReferenceData!$BL$11),"") -> 2439.4036 | BM11: =IFERROR(IF(0=LEN(ReferenceData!$BM$11),"",ReferenceData!$BM$11),"") -> 2420.9213
